<?xml version="1.0" encoding="utf-8"?>
<!-- =================================================================================== -->
<!-- |    This document was autogenerated by xacro from gripah.urdf.xacro              | -->
<!-- |    EDITING THIS FILE BY HAND IS NOT RECOMMENDED                                 | -->
<!-- =================================================================================== -->
<robot name="gripah">
  <material name="gray">
    <color rgba="0.89804 0.91765 0.92941 1"/>
  </material>
  <link name="gripah_base">
    <inertial>
      <origin rpy="0 0 0" xyz="-0.020421 1.7659E-18 6.5869E-19"/>
      <mass value="0.18"/>
      <inertia ixx="1.0" ixy="0.0" ixz="0.0" iyy="1.0" iyz="0.0" izz="1.0"/>
    </inertial>
    <visual>
      <origin rpy="0 0 0" xyz="0 0 0"/>
      <geometry>
        <mesh filename="meshes/wrist.STL"/>
      </geometry>
      <material name="gray"/>
    </visual>
    <collision>
      <origin rpy="0 0 0" xyz="0 0 0"/>
      <geometry>
        <mesh filename="meshes/wrist.STL"/>
      </geometry>
    </collision>
  </link>
  <link name="wide_finger_link">
    <inertial>
      <origin rpy="0 0 0" xyz="0.056976 0.015337 -2.3122E-09"/>
      <mass value="0.0167"/>
      <inertia ixx="1.0" ixy="-0.01" ixz="0.0" iyy="1.0" iyz="0.0" izz="1.0"/>
    </inertial>
    <visual>
      <origin rpy="0 0 0" xyz="0 0 0"/>
      <geometry>
        <mesh filename="meshes/wide_finger.STL"/>
      </geometry>
      <material name="gray"/>
    </visual>
    <collision>
      <origin rpy="0 0 0" xyz="0 0 0"/>
      <geometry>
        <mesh filename="meshes/wide_finger.STL"/>
      </geometry>
    </collision>
  </link>
  <joint name="wide_finger_joint" type="revolute">
    <origin rpy="1.5708 0.013333 -8.164E-19" xyz="0.055 0 0"/>
    <parent link="gripah_base"/>
    <child link="wide_finger_link"/>
    <axis xyz="0 0 1"/>
    <limit effort="6.6" lower="-1.0472" upper="1.0472" velocity="8.0"/>
  </joint>
  <link name="narrow_finger_link">
    <inertial>
      <origin rpy="0 0 0" xyz="0.052556 0.013896 2.3305E-07"/>
      <mass value="0.016641"/>
      <inertia ixx="1.0" ixy="-0.03" ixz="0.0" iyy="1.0" iyz="0.0" izz="1.0"/>
    </inertial>
    <visual>
      <origin rpy="0 0 0" xyz="0 0 0"/>
      <geometry>
        <mesh filename="meshes/narrow_finger.STL"/>
      </geometry>
      <material name="gray"/>
    </visual>
    <collision>
      <origin rpy="0 0 0" xyz="0 0 0"/>
      <geometry>
        <mesh filename="meshes/narrow_finger.STL"/>
      </geometry>
    </collision>
  </link>
  <joint name="narrow_finger_joint" type="revolute">
    <axis xyz="0 0 -1"/>
    <origin rpy="1.5708 0.013333 8.164E-19" xyz="0.055 0 0"/>
    <parent link="gripah_base"/>
    <child link="narrow_finger_link"/>
    <limit effort="6.6" lower="-1.0472" upper="1.0472" velocity="8.0"/>
  </joint>
</robot>

