<?xml version="0.0" ?>
<robot name="shovel.urdf">
    <material name="LightGrey">
        <color rgba="0.8 0.8 0.8 1.0"/>
    </material>

    <material name="DarkGrey">
        <color rgba="0.2 0.2 0.2 1.0"/>
    </material>

    <link name="baseLink">
        <contact>
            <lateral_friction value="1.0"/>
            <rolling_friction value="0.0001"/>
            <inertia_scaling value="3.0"/>
        </contact>
        <inertial>
            <origin rpy="0 0 0" xyz="0 0 0"/>
            <mass value=".1"/>
            <inertia ixx="1" ixy="0" ixz="0" iyy="1" iyz="0" izz="1"/>
        </inertial>
        <visual>
            <origin rpy="0 0 0" xyz="0 0 0"/>
            <geometry>
                <mesh filename="meshes/shovel_base.STL"/>
            </geometry>
            <material name="DarkGrey"/>
        </visual>
    </link>

    <joint name="baseLink-bladeLink" type="revolute">
        <axis xyz="0 1 0"/>
        <origin rpy="0 0 0" xyz="0 0 0.05"/>
        <parent link="baseLink"/>
        <child link="bladeLink"/>
        <limit effort="6.6" lower="-1.0472" upper="1.0472" velocity="8.0"/>
    </joint>

    <link name="bladeLink">
        <contact>
            <lateral_friction value="1.0"/>
            <rolling_friction value="0.0001"/>
            <inertia_scaling value="3.0"/>
        </contact>
        <inertial>
            <origin rpy="0 0 0" xyz="0 0 0"/>
            <mass value="0.02"/>
            <inertia ixx="1" ixy="0" ixz="0" iyy="1" iyz="0" izz="1"/>
        </inertial>
        <visual>
            <origin rpy="0 0 0" xyz="0 0 0"/>
            <geometry>
                <mesh filename="meshes/shovel_blade.STL"/>
            </geometry>
            <material name="LightGrey"/>
        </visual>
        <collision>
            <origin rpy="0 0 0" xyz="0 0 0"/>
            <geometry>
                <mesh filename="meshes/shovel_blade.STL"/>
            </geometry>
        </collision>
    </link>

    <joint name="bladeLink-bladeTip" type="fixed">
        <axis xyz="0 0 1"/>
        <origin xyz="0 0.002 0.15"/>
        <parent link="bladeLink"/>
        <child link="bladeTip"/>
    </joint>

    <link name="bladeTip">
        <inertial>
            <mass value="0.0"/>
            <origin rpy="0 0 0" xyz="0.0 0.0 0.0"/>
            <inertia ixx="0.0" ixy="0.0" ixz="0.0" iyy="0.0" iyz="0.0" izz="0.0"/>
        </inertial>
        <visual>
            <origin rpy="0 0 0" xyz="0 0 0"/>
            <geometry>
                <sphere radius="0.001"/>
            </geometry>
            <material name="green">
                <color rgba="0 1.0 0 1.0"/>
            </material>
        </visual>
    </link>

</robot>

